Workbook

Sheet Google Sheets Setup
B1: Open this in Google Sheets
B2: Two minutes. Step 1 is required, step 2 is optional but worth doing.
B4: Step 1 - import (required)
A5: • | B5: Go to drive.google.com and drag this .xlsx file into the window.
A6: • | B6: Once it uploads, double-click it, then choose Open with > Google Sheets.
A7: • | B7: File > Save as Google Sheets. You now have a native Google Sheet. Delete the .xlsx copy so you only ever edit one.
B8: Every formula in this workbook uses functions Google Sheets supports with identical syntax - IF, COUNTIF, INDEX, MATCH, IFERROR, TODAY, AND, OR, SUM, AVERAGE, TEXT. Nothing needs rewriting. Dropdowns and the red/green highlighting come across too.
B10: Step 2 - upgrade the Revision Today sheet (optional, 30 seconds)
B11: Excel cannot spill one formula down a whole column, so Revision Today is built from 360 separate lookups and stops at 60 rows. Google Sheets can do the same job with a single QUERY, with no row limit, sorted so the most overdue problem is always at the top. If you skip this, the sheet still works - it just caps at 60.
A12: • | B12: Open the Revision Today sheet. Select A4:G63 and press Delete. Leave column H alone.
A13: • | B13: Click cell A4 and paste this:
B14: =IFERROR(ARRAYFORMULA(IF(B4:B="","",ROW(B4:B)-3)),"")
A15: • | B15: Click cell B4 and paste this:
B16: =IFERROR(QUERY('Problem Log'!A3:V800, "select F, D, B, G, K, T where S = 'DUE' order by B", 0),"")
A17: • | B17: Done. The list now fills itself, oldest-solved first, however long it gets.
B18: The IFERROR wrapper is not optional. Until you have logged problems that are actually due, the QUERY matches no rows, and Google Sheets treats an empty result as an error rather than as blank. Wrapped, the sheet just stays empty until there is something to revise - which is what you want on day one. Nothing else in the workbook reads from this sheet, so a mistake here cannot damage your data.
B20: What not to touch
B21: Grey cells are formulas. Yellow cells are yours to type in. Column V of the Problem Log is hidden on purpose - it numbers the due problems so Revision Today can find them. If you do step 2 above, column V stops being needed, but leave it there anyway.
B23: One habit that makes or breaks this
B24: Log every problem the same morning you solve it. The revision dates are calculated from the date you type in column B, so a problem you forget to log is a problem you will never revise. Ten seconds a problem, at 9:20am, before you close the laptop.

Sheet Read Me
A1: DSA + Development Tracker
A2: 3 Aug 2026 → 14 Mar 2027 · 32 weeks · 1,344 hours · Striver A2Z in Python
A4: Your daily shape
A5: 06:30 – 06:50 | B5: Revision queue. Open the Revision Today sheet and clear it (day 2 / day 5 / day 10).
A6: 06:50 – 07:50 | B6: Learn. Striver's video or article for today's topic. Notes in your own words, not copied.
A7: 07:50 – 09:20 | B7: Practise. 2-3 new problems. Attempt for 25 min before any hint.
A8: 09:20 – 09:30 | B8: Log. Every problem goes in the Problem Log. This is what builds your revision queue.
A9: 21:00 – 23:45 | B9: Development. Weeks 1-8 your own HTML/CSS/JS sources. Weeks 9-14 Namaste React. Weeks 15-20 Namaste Node. Week 21+ interview prep.
A10: 23:45 – 00:00 | B10: Commit your code. Write tomorrow's first task on paper.
A11: Sunday | B11: No new topics. Morning = consolidation. Evening = core CS or a weekly retro.
A13: The revision rule
A14: Every problem you solve gets revisited three times: 2 days later, 5 days later, and 10 days later. The Problem Log calculates all three dates the moment you enter a solve date, and the Revision Today sheet gathers whatever is due into one list.
A15: A revision is NOT re-solving. Read the problem title, then state the approach and the time complexity out loud in under 90 seconds. If you can, tick it. If you can't, leave it unticked and re-solve the problem properly on Sunday.
A16: At steady state this is about 9 problems a day and takes roughly 20 minutes. That is why the morning starts at 6:30 and not 6:50.
A18: Colour legend
A19: Yellow cells | B19: You type here.
A20: Grey cells | B20: Formulas. Don't type over them or the revision queue breaks.
A21: Row 2 of each sheet | B21: A worked example showing the expected format. Overwrite it once you start.
A23: Sheets
A24: Problem Log | B24: The engine. Every problem, every revision date. Filter column S on 'DUE' each morning.
A25: Revision Today | B25: Open this at 6:30 every morning. It lists exactly which problems are due, on its own.
A26: Revision Dashboard | B26: Live counts: due today, overdue, needs redo, solved-alone rate, breakdown by topic.
A27: 32-Week Plan | B27: The timetable. Target vs actual problem counts pull automatically from the Problem Log.
A28: Striver Checklist | B28: All 18 A2Z steps and sub-steps, plus the topics Striver leaves out. Tick as you clear them.
A29: Daily Log | B29: Hours in, problems out, energy. Fill this in even on bad days — especially on bad days.
A30: Course Checklist | B30: Every Namaste React and Namaste Node episode, mapped to the week it belongs in.
A31: Applications | B31: From week 19. Every application, every follow-up.
A33: Two honest warnings
A34: 1. If your revision backlog climbs past about 25 problems, stop taking on new topics for two days and clear it. A backlog you never clear is the same as never having solved those problems.
A35: 2. If 'Solved alone' sits below 40% for a whole topic, you are reading editorials rather than solving. Slow down and take fewer problems. Four problems you fought for beat twelve you skimmed.

Sheet Problem Log
A1: PROBLEM LOG — enter yellow cells only. Grey columns calculate your revision dates automatically.
A2: # | B2: Date Solved | C2: Wk | D2: Topic | E2: Striver Step | F2: Problem | G2: Diff | H2: Link | I2: Solved How | J2: Mins | K2: Approach in one line | L2: Complexity | M2: R1 due (+2d) | N2: R1 ✓ | O2: R2 due (+5d) | P2: R2 ✓ | Q2: R3 due (+10d) | R2: R3 ✓ | S2: Revision Status | T2: Conf 1-5 | U2: Redo? | V2: rank
A3: =IF($F3="","",ROW()-2) -> 1 | B3: 46237 | C3: 1 | D3: Arrays | E3: Step 3.1 | F3: Second largest element | G3: Easy | H3: leetcode.com/problems/... | I3: Alone | J3: 18 | K3: Single pass, track largest and second largest separately | L3: O(n) / O(1) | M3: =IF($B3="","",$B3+2) -> 46239 | N3: Y | O3: =IF($B3="","",$B3+5) -> 46242 | Q3: =IF($B3="","",$B3+10) -> 46247 | S3: =IF($B3="","",IF(AND($N3="Y",$P3="Y",$R3="Y"),"Done",IF(OR(AND($M3<=TODAY(),$N3<>"Y"),AND($O3<=TODAY(),$P3<>"Y"),AND($Q3<=TODAY(),$R3<>"Y")),"DUE","Scheduled"))) -> Scheduled | T3: 4 | U3: =IF($B3="","",IF(OR($T3<=2,$I3="Editorial"),"REDO","")) | V3: =IF($S3<>"DUE","",COUNTIF($S$3:$S3,"DUE"))
A4: =IF($F4="","",ROW()-2) | M4: =IF($B4="","",$B4+2) | O4: =IF($B4="","",$B4+5) | Q4: =IF($B4="","",$B4+10) | S4: =IF($B4="","",IF(AND($N4="Y",$P4="Y",$R4="Y"),"Done",IF(OR(AND($M4<=TODAY(),$N4<>"Y"),AND($O4<=TODAY(),$P4<>"Y"),AND($Q4<=TODAY(),$R4<>"Y")),"DUE","Scheduled"))) | U4: =IF($B4="","",IF(OR($T4<=2,$I4="Editorial"),"REDO","")) | V4: =IF($S4<>"DUE","",COUNTIF($S$3:$S4,"DUE"))
A5: =IF($F5="","",ROW()-2) | M5: =IF($B5="","",$B5+2) | O5: =IF($B5="","",$B5+5) | Q5: =IF($B5="","",$B5+10) | S5: =IF($B5="","",IF(AND($N5="Y",$P5="Y",$R5="Y"),"Done",IF(OR(AND($M5<=TODAY(),$N5<>"Y"),AND($O5<=TODAY(),$P5<>"Y"),AND($Q5<=TODAY(),$R5<>"Y")),"DUE","Scheduled"))) | U5: =IF($B5="","",IF(OR($T5<=2,$I5="Editorial"),"REDO","")) | V5: =IF($S5<>"DUE","",COUNTIF($S$3:$S5,"DUE"))
A6: =IF($F6="","",ROW()-2) | M6: =IF($B6="","",$B6+2) | O6: =IF($B6="","",$B6+5) | Q6: =IF($B6="","",$B6+10) | S6: =IF($B6="","",IF(AND($N6="Y",$P6="Y",$R6="Y"),"Done",IF(OR(AND($M6<=TODAY(),$N6<>"Y"),AND($O6<=TODAY(),$P6<>"Y"),AND($Q6<=TODAY(),$R6<>"Y")),"DUE","Scheduled"))) | U6: =IF($B6="","",IF(OR($T6<=2,$I6="Editorial"),"REDO","")) | V6: =IF($S6<>"DUE","",COUNTIF($S$3:$S6,"DUE"))
A7: =IF($F7="","",ROW()-2) | M7: =IF($B7="","",$B7+2) | O7: =IF($B7="","",$B7+5) | Q7: =IF($B7="","",$B7+10) | S7: =IF($B7="","",IF(AND($N7="Y",$P7="Y",$R7="Y"),"Done",IF(OR(AND($M7<=TODAY(),$N7<>"Y"),AND($O7<=TODAY(),$P7<>"Y"),AND($Q7<=TODAY(),$R7<>"Y")),"DUE","Scheduled"))) | U7: =IF($B7="","",IF(OR($T7<=2,$I7="Editorial"),"REDO","")) | V7: =IF($S7<>"DUE","",COUNTIF($S$3:$S7,"DUE"))
A8: =IF($F8="","",ROW()-2) | M8: =IF($B8="","",$B8+2) | O8: =IF($B8="","",$B8+5) | Q8: =IF($B8="","",$B8+10) | S8: =IF($B8="","",IF(AND($N8="Y",$P8="Y",$R8="Y"),"Done",IF(OR(AND($M8<=TODAY(),$N8<>"Y"),AND($O8<=TODAY(),$P8<>"Y"),AND($Q8<=TODAY(),$R8<>"Y")),"DUE","Scheduled"))) | U8: =IF($B8="","",IF(OR($T8<=2,$I8="Editorial"),"REDO","")) | V8: =IF($S8<>"DUE","",COUNTIF($S$3:$S8,"DUE"))
A9: =IF($F9="","",ROW()-2) | M9: =IF($B9="","",$B9+2) | O9: =IF($B9="","",$B9+5) | Q9: =IF($B9="","",$B9+10) | S9: =IF($B9="","",IF(AND($N9="Y",$P9="Y",$R9="Y"),"Done",IF(OR(AND($M9<=TODAY(),$N9<>"Y"),AND($O9<=TODAY(),$P9<>"Y"),AND($Q9<=TODAY(),$R9<>"Y")),"DUE","Scheduled"))) | U9: =IF($B9="","",IF(OR($T9<=2,$I9="Editorial"),"REDO","")) | V9: =IF($S9<>"DUE","",COUNTIF($S$3:$S9,"DUE"))
A10: =IF($F10="","",ROW()-2) | M10: =IF($B10="","",$B10+2) | O10: =IF($B10="","",$B10+5) | Q10: =IF($B10="","",$B10+10) | S10: =IF($B10="","",IF(AND($N10="Y",$P10="Y",$R10="Y"),"Done",IF(OR(AND($M10<=TODAY(),$N10<>"Y"),AND($O10<=TODAY(),$P10<>"Y"),AND($Q10<=TODAY(),$R10<>"Y")),"DUE","Scheduled"))) | U10: =IF($B10="","",IF(OR($T10<=2,$I10="Editorial"),"REDO","")) | V10: =IF($S10<>"DUE","",COUNTIF($S$3:$S10,"DUE"))
A11: =IF($F11="","",ROW()-2) | M11: =IF($B11="","",$B11+2) | O11: =IF($B11="","",$B11+5) | Q11: =IF($B11="","",$B11+10) | S11: =IF($B11="","",IF(AND($N11="Y",$P11="Y",$R11="Y"),"Done",IF(OR(AND($M11<=TODAY(),$N11<>"Y"),AND($O11<=TODAY(),$P11<>"Y"),AND($Q11<=TODAY(),$R11<>"Y")),"DUE","Scheduled"))) | U11: =IF($B11="","",IF(OR($T11<=2,$I11="Editorial"),"REDO","")) | V11: =IF($S11<>"DUE","",COUNTIF($S$3:$S11,"DUE"))
A12: =IF($F12="","",ROW()-2) | M12: =IF($B12="","",$B12+2) | O12: =IF($B12="","",$B12+5) | Q12: =IF($B12="","",$B12+10) | S12: =IF($B12="","",IF(AND($N12="Y",$P12="Y",$R12="Y"),"Done",IF(OR(AND($M12<=TODAY(),$N12<>"Y"),AND($O12<=TODAY(),$P12<>"Y"),AND($Q12<=TODAY(),$R12<>"Y")),"DUE","Scheduled"))) | U12: =IF($B12="","",IF(OR($T12<=2,$I12="Editorial"),"REDO","")) | V12: =IF($S12<>"DUE","",COUNTIF($S$3:$S12,"DUE"))
A13: =IF($F13="","",ROW()-2) | M13: =IF($B13="","",$B13+2) | O13: =IF($B13="","",$B13+5) | Q13: =IF($B13="","",$B13+10) | S13: =IF($B13="","",IF(AND($N13="Y",$P13="Y",$R13="Y"),"Done",IF(OR(AND($M13<=TODAY(),$N13<>"Y"),AND($O13<=TODAY(),$P13<>"Y"),AND($Q13<=TODAY(),$R13<>"Y")),"DUE","Scheduled"))) | U13: =IF($B13="","",IF(OR($T13<=2,$I13="Editorial"),"REDO","")) | V13: =IF($S13<>"DUE","",COUNTIF($S$3:$S13,"DUE"))
A14: =IF($F14="","",ROW()-2) | M14: =IF($B14="","",$B14+2) | O14: =IF($B14="","",$B14+5) | Q14: =IF($B14="","",$B14+10) | S14: =IF($B14="","",IF(AND($N14="Y",$P14="Y",$R14="Y"),"Done",IF(OR(AND($M14<=TODAY(),$N14<>"Y"),AND($O14<=TODAY(),$P14<>"Y"),AND($Q14<=TODAY(),$R14<>"Y")),"DUE","Scheduled"))) | U14: =IF($B14="","",IF(OR($T14<=2,$I14="Editorial"),"REDO","")) | V14: =IF($S14<>"DUE","",COUNTIF($S$3:$S14,"DUE"))
A15: =IF($F15="","",ROW()-2) | M15: =IF($B15="","",$B15+2) | O15: =IF($B15="","",$B15+5) | Q15: =IF($B15="","",$B15+10) | S15: =IF($B15="","",IF(AND($N15="Y",$P15="Y",$R15="Y"),"Done",IF(OR(AND($M15<=TODAY(),$N15<>"Y"),AND($O15<=TODAY(),$P15<>"Y"),AND($Q15<=TODAY(),$R15<>"Y")),"DUE","Scheduled"))) | U15: =IF($B15="","",IF(OR($T15<=2,$I15="Editorial"),"REDO","")) | V15: =IF($S15<>"DUE","",COUNTIF($S$3:$S15,"DUE"))
... A800: =IF($F800="","",ROW()-2) | M800: =IF($B800="","",$B800+2) | O800: =IF($B800="","",$B800+5) | Q800: =IF($B800="","",$B800+10) | S800: =IF($B800="","",IF(AND($N800="Y",$P800="Y",$R800="Y"),"Done",IF(OR(AND($M800<=TODAY(),$N800<>"Y"),AND($O800<=TODAY(),$P800<>"Y"),AND($Q800<=TODAY(),$R800<>"Y")),"DUE","Scheduled"))) | U800: =IF($B800="","",IF(OR($T800<=2,$I800="Editorial"),"REDO","")) | V800: =IF($S800<>"DUE","",COUNTIF($S$3:$S800,"DUE"))

Sheet Revision Today
A1: REVISION TODAY - fills itself from the Problem Log. Nothing to type except the last column.
A2: Due right now: | B2: =COUNTIF('Problem Log'!$S$3:$S$800,"DUE") -> 0 | C2: Read the title, then say the approach and the complexity out loud in 90 seconds. Then tick R1/R2/R3 back in the Problem Log - that is the real record, this column is a scratch mark.
A3: # | B3: Problem | C3: Topic | D3: Solved on | E3: Diff | F3: Your approach, in one line | G3: Conf | H3: Recalled it?
A4: 1 | B4: =IFERROR(INDEX('Problem Log'!$F$3:$F$800,MATCH($A4,'Problem Log'!$V$3:$V$800,0)),"") | C4: =IFERROR(INDEX('Problem Log'!$D$3:$D$800,MATCH($A4,'Problem Log'!$V$3:$V$800,0)),"") | D4: =IFERROR(INDEX('Problem Log'!$B$3:$B$800,MATCH($A4,'Problem Log'!$V$3:$V$800,0)),"") | E4: =IFERROR(INDEX('Problem Log'!$G$3:$G$800,MATCH($A4,'Problem Log'!$V$3:$V$800,0)),"") | F4: =IFERROR(INDEX('Problem Log'!$K$3:$K$800,MATCH($A4,'Problem Log'!$V$3:$V$800,0)),"") | G4: =IFERROR(INDEX('Problem Log'!$T$3:$T$800,MATCH($A4,'Problem Log'!$V$3:$V$800,0)),"")
A5: 2 | B5: =IFERROR(INDEX('Problem Log'!$F$3:$F$800,MATCH($A5,'Problem Log'!$V$3:$V$800,0)),"") | C5: =IFERROR(INDEX('Problem Log'!$D$3:$D$800,MATCH($A5,'Problem Log'!$V$3:$V$800,0)),"") | D5: =IFERROR(INDEX('Problem Log'!$B$3:$B$800,MATCH($A5,'Problem Log'!$V$3:$V$800,0)),"") | E5: =IFERROR(INDEX('Problem Log'!$G$3:$G$800,MATCH($A5,'Problem Log'!$V$3:$V$800,0)),"") | F5: =IFERROR(INDEX('Problem Log'!$K$3:$K$800,MATCH($A5,'Problem Log'!$V$3:$V$800,0)),"") | G5: =IFERROR(INDEX('Problem Log'!$T$3:$T$800,MATCH($A5,'Problem Log'!$V$3:$V$800,0)),"")
A6: 3 | B6: =IFERROR(INDEX('Problem Log'!$F$3:$F$800,MATCH($A6,'Problem Log'!$V$3:$V$800,0)),"") | C6: =IFERROR(INDEX('Problem Log'!$D$3:$D$800,MATCH($A6,'Problem Log'!$V$3:$V$800,0)),"") | D6: =IFERROR(INDEX('Problem Log'!$B$3:$B$800,MATCH($A6,'Problem Log'!$V$3:$V$800,0)),"") | E6: =IFERROR(INDEX('Problem Log'!$G$3:$G$800,MATCH($A6,'Problem Log'!$V$3:$V$800,0)),"") | F6: =IFERROR(INDEX('Problem Log'!$K$3:$K$800,MATCH($A6,'Problem Log'!$V$3:$V$800,0)),"") | G6: =IFERROR(INDEX('Problem Log'!$T$3:$T$800,MATCH($A6,'Problem Log'!$V$3:$V$800,0)),"")
A7: 4 | B7: =IFERROR(INDEX('Problem Log'!$F$3:$F$800,MATCH($A7,'Problem Log'!$V$3:$V$800,0)),"") | C7: =IFERROR(INDEX('Problem Log'!$D$3:$D$800,MATCH($A7,'Problem Log'!$V$3:$V$800,0)),"") | D7: =IFERROR(INDEX('Problem Log'!$B$3:$B$800,MATCH($A7,'Problem Log'!$V$3:$V$800,0)),"") | E7: =IFERROR(INDEX('Problem Log'!$G$3:$G$800,MATCH($A7,'Problem Log'!$V$3:$V$800,0)),"") | F7: =IFERROR(INDEX('Problem Log'!$K$3:$K$800,MATCH($A7,'Problem Log'!$V$3:$V$800,0)),"") | G7: =IFERROR(INDEX('Problem Log'!$T$3:$T$800,MATCH($A7,'Problem Log'!$V$3:$V$800,0)),"")
A8: 5 | B8: =IFERROR(INDEX('Problem Log'!$F$3:$F$800,MATCH($A8,'Problem Log'!$V$3:$V$800,0)),"") | C8: =IFERROR(INDEX('Problem Log'!$D$3:$D$800,MATCH($A8,'Problem Log'!$V$3:$V$800,0)),"") | D8: =IFERROR(INDEX('Problem Log'!$B$3:$B$800,MATCH($A8,'Problem Log'!$V$3:$V$800,0)),"") | E8: =IFERROR(INDEX('Problem Log'!$G$3:$G$800,MATCH($A8,'Problem Log'!$V$3:$V$800,0)),"") | F8: =IFERROR(INDEX('Problem Log'!$K$3:$K$800,MATCH($A8,'Problem Log'!$V$3:$V$800,0)),"") | G8: =IFERROR(INDEX('Problem Log'!$T$3:$T$800,MATCH($A8,'Problem Log'!$V$3:$V$800,0)),"")
A9: 6 | B9: =IFERROR(INDEX('Problem Log'!$F$3:$F$800,MATCH($A9,'Problem Log'!$V$3:$V$800,0)),"") | C9: =IFERROR(INDEX('Problem Log'!$D$3:$D$800,MATCH($A9,'Problem Log'!$V$3:$V$800,0)),"") | D9: =IFERROR(INDEX('Problem Log'!$B$3:$B$800,MATCH($A9,'Problem Log'!$V$3:$V$800,0)),"") | E9: =IFERROR(INDEX('Problem Log'!$G$3:$G$800,MATCH($A9,'Problem Log'!$V$3:$V$800,0)),"") | F9: =IFERROR(INDEX('Problem Log'!$K$3:$K$800,MATCH($A9,'Problem Log'!$V$3:$V$800,0)),"") | G9: =IFERROR(INDEX('Problem Log'!$T$3:$T$800,MATCH($A9,'Problem Log'!$V$3:$V$800,0)),"")
A10: 7 | B10: =IFERROR(INDEX('Problem Log'!$F$3:$F$800,MATCH($A10,'Problem Log'!$V$3:$V$800,0)),"") | C10: =IFERROR(INDEX('Problem Log'!$D$3:$D$800,MATCH($A10,'Problem Log'!$V$3:$V$800,0)),"") | D10: =IFERROR(INDEX('Problem Log'!$B$3:$B$800,MATCH($A10,'Problem Log'!$V$3:$V$800,0)),"") | E10: =IFERROR(INDEX('Problem Log'!$G$3:$G$800,MATCH($A10,'Problem Log'!$V$3:$V$800,0)),"") | F10: =IFERROR(INDEX('Problem Log'!$K$3:$K$800,MATCH($A10,'Problem Log'!$V$3:$V$800,0)),"") | G10: =IFERROR(INDEX('Problem Log'!$T$3:$T$800,MATCH($A10,'Problem Log'!$V$3:$V$800,0)),"")
A11: 8 | B11: =IFERROR(INDEX('Problem Log'!$F$3:$F$800,MATCH($A11,'Problem Log'!$V$3:$V$800,0)),"") | C11: =IFERROR(INDEX('Problem Log'!$D$3:$D$800,MATCH($A11,'Problem Log'!$V$3:$V$800,0)),"") | D11: =IFERROR(INDEX('Problem Log'!$B$3:$B$800,MATCH($A11,'Problem Log'!$V$3:$V$800,0)),"") | E11: =IFERROR(INDEX('Problem Log'!$G$3:$G$800,MATCH($A11,'Problem Log'!$V$3:$V$800,0)),"") | F11: =IFERROR(INDEX('Problem Log'!$K$3:$K$800,MATCH($A11,'Problem Log'!$V$3:$V$800,0)),"") | G11: =IFERROR(INDEX('Problem Log'!$T$3:$T$800,MATCH($A11,'Problem Log'!$V$3:$V$800,0)),"")
A12: 9 | B12: =IFERROR(INDEX('Problem Log'!$F$3:$F$800,MATCH($A12,'Problem Log'!$V$3:$V$800,0)),"") | C12: =IFERROR(INDEX('Problem Log'!$D$3:$D$800,MATCH($A12,'Problem Log'!$V$3:$V$800,0)),"") | D12: =IFERROR(INDEX('Problem Log'!$B$3:$B$800,MATCH($A12,'Problem Log'!$V$3:$V$800,0)),"") | E12: =IFERROR(INDEX('Problem Log'!$G$3:$G$800,MATCH($A12,'Problem Log'!$V$3:$V$800,0)),"") | F12: =IFERROR(INDEX('Problem Log'!$K$3:$K$800,MATCH($A12,'Problem Log'!$V$3:$V$800,0)),"") | G12: =IFERROR(INDEX('Problem Log'!$T$3:$T$800,MATCH($A12,'Problem Log'!$V$3:$V$800,0)),"")
A13: 10 | B13: =IFERROR(INDEX('Problem Log'!$F$3:$F$800,MATCH($A13,'Problem Log'!$V$3:$V$800,0)),"") | C13: =IFERROR(INDEX('Problem Log'!$D$3:$D$800,MATCH($A13,'Problem Log'!$V$3:$V$800,0)),"") | D13: =IFERROR(INDEX('Problem Log'!$B$3:$B$800,MATCH($A13,'Problem Log'!$V$3:$V$800,0)),"") | E13: =IFERROR(INDEX('Problem Log'!$G$3:$G$800,MATCH($A13,'Problem Log'!$V$3:$V$800,0)),"") | F13: =IFERROR(INDEX('Problem Log'!$K$3:$K$800,MATCH($A13,'Problem Log'!$V$3:$V$800,0)),"") | G13: =IFERROR(INDEX('Problem Log'!$T$3:$T$800,MATCH($A13,'Problem Log'!$V$3:$V$800,0)),"")
A14: 11 | B14: =IFERROR(INDEX('Problem Log'!$F$3:$F$800,MATCH($A14,'Problem Log'!$V$3:$V$800,0)),"") | C14: =IFERROR(INDEX('Problem Log'!$D$3:$D$800,MATCH($A14,'Problem Log'!$V$3:$V$800,0)),"") | D14: =IFERROR(INDEX('Problem Log'!$B$3:$B$800,MATCH($A14,'Problem Log'!$V$3:$V$800,0)),"") | E14: =IFERROR(INDEX('Problem Log'!$G$3:$G$800,MATCH($A14,'Problem Log'!$V$3:$V$800,0)),"") | F14: =IFERROR(INDEX('Problem Log'!$K$3:$K$800,MATCH($A14,'Problem Log'!$V$3:$V$800,0)),"") | G14: =IFERROR(INDEX('Problem Log'!$T$3:$T$800,MATCH($A14,'Problem Log'!$V$3:$V$800,0)),"")
A15: 12 | B15: =IFERROR(INDEX('Problem Log'!$F$3:$F$800,MATCH($A15,'Problem Log'!$V$3:$V$800,0)),"") | C15: =IFERROR(INDEX('Problem Log'!$D$3:$D$800,MATCH($A15,'Problem Log'!$V$3:$V$800,0)),"") | D15: =IFERROR(INDEX('Problem Log'!$B$3:$B$800,MATCH($A15,'Problem Log'!$V$3:$V$800,0)),"") | E15: =IFERROR(INDEX('Problem Log'!$G$3:$G$800,MATCH($A15,'Problem Log'!$V$3:$V$800,0)),"") | F15: =IFERROR(INDEX('Problem Log'!$K$3:$K$800,MATCH($A15,'Problem Log'!$V$3:$V$800,0)),"") | G15: =IFERROR(INDEX('Problem Log'!$T$3:$T$800,MATCH($A15,'Problem Log'!$V$3:$V$800,0)),"")
... A63: 60 | B63: =IFERROR(INDEX('Problem Log'!$F$3:$F$800,MATCH($A63,'Problem Log'!$V$3:$V$800,0)),"") | C63: =IFERROR(INDEX('Problem Log'!$D$3:$D$800,MATCH($A63,'Problem Log'!$V$3:$V$800,0)),"") | D63: =IFERROR(INDEX('Problem Log'!$B$3:$B$800,MATCH($A63,'Problem Log'!$V$3:$V$800,0)),"") | E63: =IFERROR(INDEX('Problem Log'!$G$3:$G$800,MATCH($A63,'Problem Log'!$V$3:$V$800,0)),"") | F63: =IFERROR(INDEX('Problem Log'!$K$3:$K$800,MATCH($A63,'Problem Log'!$V$3:$V$800,0)),"") | G63: =IFERROR(INDEX('Problem Log'!$T$3:$T$800,MATCH($A63,'Problem Log'!$V$3:$V$800,0)),"")

Sheet Revision Dashboard
A1: REVISION DASHBOARD
A2: Everything here reads from the Problem Log. Reopen the file to refresh.
A4: Today | B4: =TODAY() -> 46233 | D4: Problems by topic
D5: Topic | E5: Solved
A6: Problems logged | B6: =COUNT('Problem Log'!$B$3:$B$800) -> 1 | D6: Python basics | E6: =COUNTIF('Problem Log'!$D$3:$D$800,$D6) -> 0
A7: Revisions DUE now | B7: =COUNTIF('Problem Log'!$S$3:$S$800,"DUE") -> 0 | D7: Sorting | E7: =COUNTIF('Problem Log'!$D$3:$D$800,$D7) -> 0
A8: Scheduled (not yet due) | B8: =COUNTIF('Problem Log'!$S$3:$S$800,"Scheduled") -> 1 | D8: Arrays | E8: =COUNTIF('Problem Log'!$D$3:$D$800,$D8) -> 1
A9: Fully revised (all 3 done) | B9: =COUNTIF('Problem Log'!$S$3:$S$800,"Done") -> 0 | D9: Binary Search | E9: =COUNTIF('Problem Log'!$D$3:$D$800,$D9) -> 0
A10: Flagged for a full redo | B10: =COUNTIF('Problem Log'!$U$3:$U$800,"REDO") -> 0 | D10: Strings | E10: =COUNTIF('Problem Log'!$D$3:$D$800,$D10) -> 0
D11: Linked List | E11: =COUNTIF('Problem Log'!$D$3:$D$800,$D11) -> 0
A12: Solved alone | B12: =COUNTIF('Problem Log'!$I$3:$I$800,"Alone") -> 1 | D12: Recursion | E12: =COUNTIF('Problem Log'!$D$3:$D$800,$D12) -> 0
A13: Needed a hint | B13: =COUNTIF('Problem Log'!$I$3:$I$800,"Hint") -> 0 | D13: Bit Manipulation | E13: =COUNTIF('Problem Log'!$D$3:$D$800,$D13) -> 0
A14: Needed the editorial | B14: =COUNTIF('Problem Log'!$I$3:$I$800,"Editorial") -> 0 | D14: Stacks & Queues | E14: =COUNTIF('Problem Log'!$D$3:$D$800,$D14) -> 0
A15: Solved-alone rate | B15: =IFERROR(COUNTIF('Problem Log'!$I$3:$I$800,"Alone")/COUNT('Problem Log'!$B$3:$B$800),"") -> 1 | D15: Sliding Window | E15: =COUNTIF('Problem Log'!$D$3:$D$800,$D15) -> 0
D16: Heaps | E16: =COUNTIF('Problem Log'!$D$3:$D$800,$D16) -> 0
A17: Easy | B17: =COUNTIF('Problem Log'!$G$3:$G$800,"Easy") -> 1 | D17: Greedy | E17: =COUNTIF('Problem Log'!$D$3:$D$800,$D17) -> 0
A18: Medium | B18: =COUNTIF('Problem Log'!$G$3:$G$800,"Medium") -> 0 | D18: Binary Trees | E18: =COUNTIF('Problem Log'!$D$3:$D$800,$D18) -> 0
A19: Hard | B19: =COUNTIF('Problem Log'!$G$3:$G$800,"Hard") -> 0 | D19: BST | E19: =COUNTIF('Problem Log'!$D$3:$D$800,$D19) -> 0
D20: Graphs | E20: =COUNTIF('Problem Log'!$D$3:$D$800,$D20) -> 0
A21: Average confidence | B21: =IFERROR(AVERAGE('Problem Log'!$T$3:$T$800),"") -> 4 | D21: DP | E21: =COUNTIF('Problem Log'!$D$3:$D$800,$D21) -> 0
A22: Average minutes per problem | B22: =IFERROR(AVERAGE('Problem Log'!$J$3:$J$800),"") -> 18 | D22: Tries | E22: =COUNTIF('Problem Log'!$D$3:$D$800,$D22) -> 0
A23: Total hours logged (Daily Log) | B23: =IFERROR(SUM('Daily Log'!$E$3:$E$300),0) -> 6 | D23: Segment Tree | E23: =COUNTIF('Problem Log'!$D$3:$D$800,$D23) -> 0
A27: If 'Revisions DUE now' goes above 25, pause new topics for two days and clear it. That number is the health check for the whole system.

Sheet 32-Week Plan
A1: 32-WEEK PLAN — 'Actual' counts automatically from the Week column in your Problem Log.
A2: Wk | B2: Starts | C2: Ends | D2: Phase | E2: Morning - DSA | F2: Striver Step | G2: Night - Dev / Prep | H2: Target | I2: Actual | J2: Gap | K2: Status
A3: 1 | B3: 46237 | C3: 46243 | D3: Rebuild the foundation | E3: Python refresher + Big-O | F3: Step 1.1-1.2 | G3: HTML - structure & semantics | H3: 16 | I3: =COUNTIF('Problem Log'!$C$3:$C$800,$A3) -> 1 | J3: =IF($I3="","",$I3-$H3) -> -15
A4: 2 | B4: 46244 | C4: 46250 | D4: Rebuild the foundation | E4: Python data structures + maths + hashing | F4: Step 1.3-1.6 | G4: CSS fundamentals | H4: 18 | I4: =COUNTIF('Problem Log'!$C$3:$C$800,$A4) -> 0 | J4: =IF($I4="","",$I4-$H4) -> -18
A5: 3 | B5: 46251 | C5: 46257 | D5: Rebuild the foundation | E5: Sorting algorithms + Arrays (easy) | F5: Step 2 + 3.1 | G5: CSS Grid, responsive, Tailwind | H5: 18 | I5: =COUNTIF('Problem Log'!$C$3:$C$800,$A5) -> 0 | J5: =IF($I5="","",$I5-$H5) -> -18
A6: 4 | B6: 46258 | C6: 46264 | D6: Rebuild the foundation | E6: Arrays (medium) | F6: Step 3.2 | G6: Git, GitHub, deployment | H6: 16 | I6: =COUNTIF('Problem Log'!$C$3:$C$800,$A6) -> 0 | J6: =IF($I6="","",$I6-$H6) -> -16
A7: 5 | B7: 46265 | C7: 46271 | D7: Arrays & binary search | E7: Arrays (hard) + intervals | F7: Step 3.3 + extra | G7: JavaScript fundamentals I | H7: 16 | I7: =COUNTIF('Problem Log'!$C$3:$C$800,$A7) -> 0 | J7: =IF($I7="","",$I7-$H7) -> -16
A8: 6 | B8: 46272 | C8: 46278 | D8: Arrays & binary search | E8: Binary search on 1D arrays | F8: Step 4.1 | G8: JavaScript II - the DOM | H8: 14 | I8: =COUNTIF('Problem Log'!$C$3:$C$800,$A8) -> 0 | J8: =IF($I8="","",$I8-$H8) -> -14
A9: 7 | B9: 46279 | C9: 46285 | D9: Arrays & binary search | E9: Binary search on answers + 2D | F9: Step 4.2-4.3 | G9: JavaScript III - async | H9: 15 | I9: =COUNTIF('Problem Log'!$C$3:$C$800,$A9) -> 0 | J9: =IF($I9="","",$I9-$H9) -> -15
A10: 8 | B10: 46286 | C10: 46292 | D10: Arrays & binary search | E10: Strings (basic + medium) | F10: Step 5 | G10: JavaScript project week | H10: 15 | I10: =COUNTIF('Problem Log'!$C$3:$C$800,$A10) -> 0 | J10: =IF($I10="","",$I10-$H10) -> -15
A11: 9 | B11: 46293 | C11: 46299 | D11: Pointers & recursion | E11: Linked lists - singly & doubly | F11: Step 6.1-6.2 | G11: Namaste React - Ep 01-04 | H11: 15 | I11: =COUNTIF('Problem Log'!$C$3:$C$800,$A11) -> 0 | J11: =IF($I11="","",$I11-$H11) -> -15
A12: 10 | B12: 46300 | C12: 46306 | D12: Pointers & recursion | E12: Linked lists - medium & hard | F12: Step 6.3-6.4 | G12: Namaste React - Ep 05-07 | H12: 14 | I12: =COUNTIF('Problem Log'!$C$3:$C$800,$A12) -> 0 | J12: =IF($I12="","",$I12-$H12) -> -14
A13: 11 | B13: 46307 | C13: 46313 | D13: Pointers & recursion | E13: Recursion & subsequences | F13: Step 7.1-7.2 | G13: Namaste React - Ep 08-10 | H13: 14 | I13: =COUNTIF('Problem Log'!$C$3:$C$800,$A13) -> 0 | J13: =IF($I13="","",$I13-$H13) -> -14
A14: 12 | B14: 46314 | C14: 46320 | D14: Pointers & recursion | E14: Backtracking | F14: Step 7.3 | G14: Namaste React - Ep 11-13 | H14: 12 | I14: =COUNTIF('Problem Log'!$C$3:$C$800,$A14) -> 0 | J14: =IF($I14="","",$I14-$H14) -> -12
... A34: 32 | B34: 46454 | C34: 46460 | D34: Sprint & interviews | E34: Peak & interview | F34: Final | G34: Interviewing | H34: 12 | I34: =COUNTIF('Problem Log'!$C$3:$C$800,$A34) -> 0 | J34: =IF($I34="","",$I34-$H34) -> -12
G35: TOTAL | H35: =SUM($H$3:$H$34) -> 471 | I35: =SUM($I$3:$I$34) -> 1 | J35: =SUM($J$3:$J$34) -> -470

Sheet Striver Checklist
A1: STRIVER A2Z — all 18 steps. Rows marked 'ADDED' are topics Striver's sheet leaves out but product companies still ask.
A2: Step | B2: Section | C2: Sub-step | D2: Problems | E2: Planned Wk | F2: Started | G2: Cleared | H2: Notes
A3: 1 | B3: Learn the basics | C3: 1.1 Things to know / patterns | D3: 8 | E3: 1
A4: 1 | B4: Learn the basics | C4: 1.2 Build-up logical thinking (patterns) | D4: 1 | E4: 1
A5: 1 | B5: Learn the basics | C5: 1.3 Learn STL / Python collections | D5: 2 | E5: 2
A6: 1 | B6: Learn the basics | C6: 1.4 Know basic maths | D6: 7 | E6: 2
A7: 1 | B7: Learn the basics | C7: 1.5 Learn basic recursion | D7: 9 | E7: 2
A8: 1 | B8: Learn the basics | C8: 1.6 Learn basic hashing | D8: 3 | E8: 2
A9: 2 | B9: Sorting techniques | C9: 2.1 Sorting-I (selection, bubble, insertion) | D9: 3 | E9: 3
A10: 2 | B10: Sorting techniques | C10: 2.2 Sorting-II (merge, quick, recursive) | D10: 4 | E10: 3
A11: 3 | B11: Arrays | C11: 3.1 Easy | D11: 14 | E11: 3
A12: 3 | B12: Arrays | C12: 3.2 Medium | D12: 14 | E12: 4
A13: 3 | B13: Arrays | C13: 3.3 Hard | D13: 12 | E13: 5
A14: + | B14: ADDED - not in A2Z | C14: Intervals & sweep line | D14: 5 | E14: 5
A15: 4 | B15: Binary Search | C15: 4.1 BS on 1D arrays | D15: 13 | E15: 6
A16: 4 | B16: Binary Search | C16: 4.2 BS on answers | D16: 11 | E16: 7
A17: 4 | B17: Binary Search | C17: 4.3 BS on 2D arrays | D17: 4 | E17: 7
A18: 5 | B18: Strings | C18: 5.1 Basic and easy | D18: 7 | E18: 8
A19: 5 | B19: Strings | C19: 5.2 Medium | D19: 8 | E19: 8
A20: 6 | B20: Linked List | C20: 6.1 Learn 1D linked list | D20: 5 | E20: 9
A21: 6 | B21: Linked List | C21: 6.2 Learn doubly linked list | D21: 4 | E21: 9
A22: 6 | B22: Linked List | C22: 6.3 Medium problems | D22: 15 | E22: 10
A23: 6 | B23: Linked List | C23: 6.4 Hard problems | D23: 7 | E23: 10
A24: 7 | B24: Recursion | C24: 7.1 Get a strong hold | D24: 5 | E24: 11
A25: 7 | B25: Recursion | C25: 7.2 Subsequences pattern | D25: 12 | E25: 11
A26: 7 | B26: Recursion | C26: 7.3 Trying all combos / hard | D26: 8 | E26: 12
... A29: 8 | B29: Bit Manipulation | C29: 8.3 Advanced maths | D29: 4 | E29: 13
A30: + | B30: ADDED - not in A2Z | C30: Number theory: modular arithmetic, mod inverse | D30: 3 | E30: 13
A31: 9 | B31: Stacks & Queues | C31: 9.1 Learn implementation | D31: 9 | E31: 14
A32: 9 | B32: Stacks & Queues | C32: 9.2 Prefix, infix, postfix | D32: 6 | E32: 14
A33: 9 | B33: Stacks & Queues | C33: 9.3 Monotonic stack / queue | D33: 11 | E33: 15
A34: 9 | B34: Stacks & Queues | C34: 9.4 Implementation problems | D34: 5 | E34: 15
A35: 10 | B35: Sliding Window | C35: 10.1 Medium problems | D35: 8 | E35: 16
A36: 10 | B36: Sliding Window | C36: 10.2 Hard problems | D36: 4 | E36: 16
A37: 11 | B37: Heaps | C37: 11.1 Learn theory | D37: 2 | E37: 17
A38: 11 | B38: Heaps | C38: 11.2 Medium problems | D38: 7 | E38: 17
A39: 11 | B39: Heaps | C39: 11.3 Hard problems | D39: 5 | E39: 17
A40: 12 | B40: Greedy | C40: 12.1 Easy problems | D40: 5 | E40: 18
A41: 12 | B41: Greedy | C41: 12.2 Medium / hard | D41: 11 | E41: 18
A42: 13 | B42: Binary Trees | C42: 13.1 Traversals | D42: 13 | E42: 19
...

Sheet Daily Log
A1: DAILY LOG — fill this in even on the bad days. Especially on the bad days.
A2: Date | B2: Day | C2: Morning hrs | D2: Evening hrs | E2: Total | F2: New problems | G2: Revisions cleared | H2: Energy 1-5 | I2: What went wrong today | J2: Fix for tomorrow
A3: 46237 | B3: =IF($A3="","",TEXT($A3,"ddd")) -> Mon | C3: 3 | D3: 3 | E3: =IF($A3="","",N($C3)+N($D3)) -> 6 | F3: 3 | G3: 0 | H3: 4 | I3: Lost 20 min deciding what to start with | J3: Write tomorrow's first task before bed
B4: =IF($A4="","",TEXT($A4,"ddd")) | E4: =IF($A4="","",N($C4)+N($D4))
B5: =IF($A5="","",TEXT($A5,"ddd")) | E5: =IF($A5="","",N($C5)+N($D5))
B6: =IF($A6="","",TEXT($A6,"ddd")) | E6: =IF($A6="","",N($C6)+N($D6))
B7: =IF($A7="","",TEXT($A7,"ddd")) | E7: =IF($A7="","",N($C7)+N($D7))
B8: =IF($A8="","",TEXT($A8,"ddd")) | E8: =IF($A8="","",N($C8)+N($D8))
B9: =IF($A9="","",TEXT($A9,"ddd")) | E9: =IF($A9="","",N($C9)+N($D9))
B10: =IF($A10="","",TEXT($A10,"ddd")) | E10: =IF($A10="","",N($C10)+N($D10))
B11: =IF($A11="","",TEXT($A11,"ddd")) | E11: =IF($A11="","",N($C11)+N($D11))
B12: =IF($A12="","",TEXT($A12,"ddd")) | E12: =IF($A12="","",N($C12)+N($D12))
B13: =IF($A13="","",TEXT($A13,"ddd")) | E13: =IF($A13="","",N($C13)+N($D13))
B14: =IF($A14="","",TEXT($A14,"ddd")) | E14: =IF($A14="","",N($C14)+N($D14))
B15: =IF($A15="","",TEXT($A15,"ddd")) | E15: =IF($A15="","",N($C15)+N($D15))
... B300: =IF($A300="","",TEXT($A300,"ddd")) | E300: =IF($A300="","",N($C300)+N($D300))

Sheet Applications
A1: APPLICATIONS — starts week 19 (7 Dec 2026). Anything with no contact for 10+ days needs a follow-up.
A2: Date applied | B2: Company | C2: Role | D2: Source | E2: Status | F2: Last contact | G2: Days since | H2: Next action | I2: Notes
A3: 46361 | B3: Example Corp | C3: SDE-1 Backend | D3: Referral | E3: Applied | F3: 46361 | G3: =IF($F3="","",TODAY()-$F3) -> -128 | H3: Follow up if no reply by 15 Dec | I3: Referred by X, mentioned the real-time project
G4: =IF($F4="","",TODAY()-$F4)
G5: =IF($F5="","",TODAY()-$F5)
G6: =IF($F6="","",TODAY()-$F6)
G7: =IF($F7="","",TODAY()-$F7)
G8: =IF($F8="","",TODAY()-$F8)
G9: =IF($F9="","",TODAY()-$F9)
G10: =IF($F10="","",TODAY()-$F10)
G11: =IF($F11="","",TODAY()-$F11)
G12: =IF($F12="","",TODAY()-$F12)
G13: =IF($F13="","",TODAY()-$F13)
G14: =IF($F14="","",TODAY()-$F14)
G15: =IF($F15="","",TODAY()-$F15)
... G202: =IF($F202="","",TODAY()-$F202)

Sheet Course Checklist
A1: NAMASTE REACT + NAMASTE NODE - tick 'Watched' only after you have also built along. Watching alone does not count.
A2: Course | B2: Section | C2: Episode | D2: Planned Wk | E2: Watched | F2: Built it | G2: Notes / where I got stuck
A3: React | B3: Namaste React Web Series | C3: Important Guidelines - read first | D3: 9
A4: React | B4: Namaste React Web Series | C4: Ep 01 | Inception | D4: 9
A5: React | B5: Namaste React Web Series | C5: Ep 02 | Igniting our App | D5: 9
A6: React | B6: Namaste React Web Series | C6: Ep 03 | Laying the foundation | D6: 9
A7: React | B7: Namaste React Web Series | C7: Ep 04 | Talk is Cheap, Show Me the Code | D7: 9
A8: React | B8: Namaste React Web Series | C8: Swiggy Dummy Data API documentation | D8: 9
A9: React | B9: Namaste React Web Series | C9: Ep 05 | Let's Get Hooked | D9: 10
A10: React | B10: Namaste React Web Series | C10: Ep 06 | Exploring the World | D10: 10
A11: React | B11: Namaste React Web Series | C11: Ep 6.1 | Swiggy API issue resolved | D11: 10
A12: React | B12: Namaste React Web Series | C12: Ep 6.2 | CORS plugin issue solved | D12: 10
A13: React | B13: Namaste React Web Series | C13: Ep 07 | Finding the Path | D13: 10
A14: React | B14: Namaste React Web Series | C14: Ep 08 | Let's Get Classy | D14: 11
... A79: Note | B79: - | C79: React course lists DevTinder UI as bonus - identical to Node S2 Ep 15-19, scheduled once in wk 19 | D79: 19
C80: TOTAL BUILT | F80: =COUNTIF($F$3:$F$79,"Y")&" / 77" -> 0 / 77
